Workbook

Sheet AN
C1: Anaheim
C2: Per Restaurant
C3: Chage Order Deposits | D3: Change Order Received | E3: Initials | F3: Comments | H3: Cash over/ (Short) per R365 Flash report | I3: True Over/ (Short)
B4: =Control!$B$3 -> 46243 | C4: 0 | D4: 1100 | E4: AR | F4: Prior Period 8 owed $1,100 | I4: =H4-C4 -> 0
B5: =B4+1 -> 46244 | C5: 0 | D5: 0 | E5: Ld | H5: 0 | I5: =H5-C5 -> 0
B6: =B5+1 -> 46245 | C6: 0 | D6: 1800 | E6: AR | H6: 0 | I6: =H6-C6 -> 0
B7: =B6+1 -> 46246 | C7: 0 | D7: 0 | E7: Ld | H7: 0 | I7: =H7-C7 -> 0
B8: =B7+1 -> 46247 | C8: -1300 | D8: 0 | E8: AR | H8: 0 | I8: =H8-C8 -> 1300
B9: =B8+1 -> 46248 | C9: 0 | D9: 0 | H9: 0 | I9: =H9-C9 -> 0
B10: =B9+1 -> 46249 | C10: 0 | D10: 0 | H10: 0 | I10: =H10-C10 -> 0
B11: Total Week | C11: =SUM(C4:C10) -> -1300 | D11: =SUM(D4:D10) -> 2900 | H11: =SUM(H4:H10) -> 0 | I11: =SUM(I4:I10) -> 1300
B12: =B10+1 -> 46250 | C12: 0 | D12: 0 | I12: =H12-C12 -> 0
B13: =B12+1 -> 46251 | C13: 0 | D13: 0 | E13: Ld | I13: =H13-C13 -> 0
B14: =B13+1 -> 46252 | C14: 0 | D14: 0 | I14: =H14-C14 -> 0
B15: =B14+1 -> 46253 | C15: -1500 | D15: 700 | E15: AR | I15: =H15-C15 -> 1500
B16: =B15+1 -> 46254 | C16: 0 | D16: 0 | I16: =H16-C16 -> 0
B17: =B16+1 -> 46255 | C17: 0 | D17: 0 | I17: =H17-C17 -> 0
B18: =B17+1 -> 46256 | C18: 0 | D18: 0 | I18: =H18-C18 -> 0
B19: Total Week | C19: =SUM(C12:C18) -> -1500 | D19: =SUM(D12:D18) -> 700 | H19: =SUM(H12:H18) -> 0 | I19: =SUM(I12:I18) -> 1500
B20: =B18+1 -> 46257 | C20: 0 | D20: 0 | I20: =H20-C20 -> 0
B21: =B20+1 -> 46258 | C21: 0 | D21: 0 | I21: =H21-C21 -> 0
B22: =B21+1 -> 46259 | C22: 0 | D22: 2020 | E22: AR | I22: =H22-C22 -> 0
B23: =B22+1 -> 46260 | C23: -820 | D23: 0 | E23: AR | I23: =H23-C23 -> 820
B24: =B23+1 -> 46261 | C24: 0 | D24: 0 | I24: =H24-C24 -> 0
B25: =B24+1 -> 46262 | C25: 0 | D25: 0 | I25: =H25-C25 -> 0
B26: =B25+1 -> 46263 | C26: -800 | D26: 0 | I26: =H26-C26 -> 800
B27: Total Week | C27: =SUM(C20:C26) -> -1620 | D27: =SUM(D20:D26) -> 2020 | H27: =SUM(H20:H26) -> 0 | I27: =SUM(I20:I26) -> 1620
B28: =B26+1 -> 46264 | C28: 0 | D28: 0 | I28: =H28-C28 -> 0
B29: =B28+1 -> 46265 | C29: 0 | D29: 0 | I29: =H29-C29 -> 0
B30: =B29+1 -> 46266 | C30: 0 | D30: 0 | I30: =H30-C30 -> 0
B31: =B30+1 -> 46267 | C31: 0 | D31: 0 | I31: =H31-C31 -> 0
B32: =B31+1 -> 46268 | C32: 0 | D32: 0 | I32: =H32-C32 -> 0
B33: =B32+1 -> 46269 | C33: -1250 | D33: 2450 | E33: AR | I33: =H33-C33 -> 1250
B34: =B33+1 -> 46270 | C34: -300 | D34: 0 | E34: AR | I34: =H34-C34 -> 300
B35: Total Week | C35: =SUM(C28:C34) -> -1550 | D35: =SUM(D28:D34) -> 2450 | H35: =SUM(H28:H34) -> 0 | I35: =SUM(I28:I34) -> 1550
B36: Total Period | C36: =SUM(C35+C27+C19+C11) -> -5970 | D36: =SUM(D35+D27+D19+D11) -> 8070 | H36: =SUM(H35+H27+H19+H11) -> 0 | I36: =SUM(I35+I27+I19+I11) -> 5970
B37: Period Activity | C37: =D36+C36 -> 2100 | H37: =I36+H36 -> 5970 | I37: =J36+I36 -> 5970
C38: =B34+1 -> 46271 | D38: After Period Close
B39: Ending Period Count of Amount on hand | C39: 2100 | E39: AR
B41: Number of Cash Drawers | C41: 2
...

Sheet CL
C1: Claremont
C2: Per Restaurant
C3: Chage Order Deposits | D3: Change Order Received | E3: Initials | F3: Comments | H3: Cash over/ (Short) per R365 Flash report | I3: True Over/ (Short)
B4: =Control!$B$3 -> 46243 | C4: 0 | D4: 0 | I4: =H4-C4 -> 0
B5: =B4+1 -> 46244 | C5: 0 | D5: 0 | I5: =H5-C5 -> 0
B6: =B5+1 -> 46245 | C6: 0 | D6: 0 | I6: =H6-C6 -> 0
B7: =B6+1 -> 46246 | C7: -950 | D7: 2200 | E7: YT | I7: =H7-C7 -> 950
B8: =B7+1 -> 46247 | C8: 0 | D8: 0 | I8: =H8-C8 -> 0
B9: =B8+1 -> 46248 | C9: -500 | D9: 0 | E9: YT | I9: =H9-C9 -> 500
B10: =B9+1 -> 46249 | C10: 0 | D10: 0 | I10: =H10-C10 -> 0
B11: Total Week | C11: =SUM(C4:C10) -> -1450 | D11: =SUM(D4:D10) -> 2200 | H11: =SUM(H4:H10) -> 0 | I11: =SUM(I4:I10) -> 1450
B12: =B10+1 -> 46250 | C12: 0 | D12: 0 | I12: =H12-C12 -> 0
B13: =B12+1 -> 46251 | C13: 0 | D13: 0 | I13: =H13-C13 -> 0
B14: =B13+1 -> 46252 | C14: 0 | D14: 0 | I14: =H14-C14 -> 0
B15: =B14+1 -> 46253 | C15: 0 | D15: 1175 | E15: YT | I15: =H15-C15 -> 0
B16: =B15+1 -> 46254 | C16: -1500 | D16: 0 | E16: YT | I16: =H16-C16 -> 1500
B17: =B16+1 -> 46255 | C17: 0 | D17: 0 | I17: =H17-C17 -> 0
B18: =B17+1 -> 46256 | C18: -710 | D18: 0 | E18: YT | I18: =H18-C18 -> 710
B19: Total Week | C19: =SUM(C12:C18) -> -2210 | D19: =SUM(D12:D18) -> 1175 | H19: =SUM(H12:H18) -> 0 | I19: =SUM(I12:I18) -> 2210
B20: =B18+1 -> 46257 | C20: 0 | D20: 0 | I20: =H20-C20 -> 0
B21: =B20+1 -> 46258 | C21: 0 | D21: 0 | I21: =H21-C21 -> 0
B22: =B21+1 -> 46259 | C22: 0 | D22: 0 | I22: =H22-C22 -> 0
B23: =B22+1 -> 46260 | C23: -1110 | D23: 1550 | E23: YT | I23: =H23-C23 -> 1110
B24: =B23+1 -> 46261 | C24: 0 | D24: 0 | H24: 0 | I24: =H24-C24 -> 0
B25: =B24+1 -> 46262 | C25: 0 | D25: 0 | H25: 0 | I25: =H25-C25 -> 0
B26: =B25+1 -> 46263 | C26: 0 | D26: 0 | H26: 0 | I26: =H26-C26 -> 0
B27: Total Week | C27: =SUM(C20:C26) -> -1110 | D27: =SUM(D20:D26) -> 1550 | H27: =SUM(H20:H26) -> 0 | I27: =SUM(I20:I26) -> 1110
B28: =B26+1 -> 46264 | C28: 0 | D28: 0 | I28: 0
B29: =B28+1 -> 46265 | C29: 0 | D29: 0 | I29: =H29-C29 -> 0
B30: =B29+1 -> 46266 | D30: 2025 | E30: BH | F30: Chng order received | I30: =H30-C30 -> 0
B31: =B30+1 -> 46267 | C31: -2210 | E31: YT | F31: Chng order paid(Short $53 actual for the Day) | I31: =H31-C31 -> 2210
B32: =B31+1 -> 46268 | C32: 0 | D32: 0 | I32: =H32-C32 -> 0
B33: =B32+1 -> 46269 | C33: 0 | D33: 0 | I33: =H33-C33 -> 0
B34: =B33+1 -> 46270 | C34: 0 | D34: 0 | I34: =H34-C34 -> 0
B35: Total Week | C35: =SUM(C28:C34) -> -2210 | D35: =SUM(D28:D34) -> 2025 | H35: =SUM(H28:H34) -> 0 | I35: =SUM(I28:I34) -> 2210
B36: Total Period | C36: =SUM(C35+C27+C19+C11) -> -6980 | D36: =SUM(D35+D27+D19+D11) -> 6950 | H36: =SUM(H35+H27+H19+H11) -> 0 | I36: =SUM(I35+I27+I19+I11) -> 6980
B37: Period Activity | C37: =D36+C36 -> -30 | H37: =I36+H36 -> 6980 | I37: =J36+I36 -> 6980
C38: =B34+1 -> 46271 | D38: After Period Close
B39: Ending Period Count of Amount on hand | C39: 1630 | E39: YT
B41: Number of Cash Drawers | C41: 2
...

Sheet CM
C1: Costa Mesa
C2: Per Restaurant
C3: Chage Order Deposits | D3: Change Order Received | E3: Initials | F3: Comments | H3: Cash over/ (Short) per R365 Flash report | I3: True Over/ (Short)
B4: =Control!$B$3 -> 46243 | C4: 0 | D4: 0 | I4: =H4-C4 -> 0
B5: =B4+1 -> 46244 | C5: 0 | D5: 0 | I5: =H5-C5 -> 0
B6: =B5+1 -> 46245 | C6: 0 | D6: 0 | I6: =H6-C6 -> 0
B7: =B6+1 -> 46246 | C7: 0 | D7: 1050 | E7: cn | I7: =H7-C7 -> 0
B8: =B7+1 -> 46247 | C8: 0 | D8: 0 | I8: =H8-C8 -> 0
B9: =B8+1 -> 46248 | C9: 0 | D9: 0 | I9: =H9-C9 -> 0
B10: =B9+1 -> 46249 | C10: 0 | D10: 0 | I10: =H10-C10 -> 0
B11: Total Week | C11: =SUM(C4:C10) -> 0 | D11: =SUM(D4:D10) -> 1050 | E11: cn | H11: =SUM(H4:H10) -> 0 | I11: =SUM(I4:I10) -> 0
B12: =B10+1 -> 46250 | C12: 0 | D12: 0 | I12: =H12-C12 -> 0
B13: =B12+1 -> 46251 | C13: 0 | D13: 0 | I13: =H13-C13 -> 0
B14: =B13+1 -> 46252 | C14: 0 | D14: 0 | I14: =H14-C14 -> 0
B15: =B14+1 -> 46253 | C15: -1050 | D15: 900 | E15: cn | I15: =H15-C15 -> 1050
B16: =B15+1 -> 46254 | C16: 0 | D16: 0 | I16: =H16-C16 -> 0
B17: =B16+1 -> 46255 | C17: 0 | D17: 0 | I17: =H17-C17 -> 0
B18: =B17+1 -> 46256 | C18: 0 | D18: 0 | I18: =H18-C18 -> 0
B19: Total Week | C19: =SUM(C12:C18) -> -1050 | D19: =SUM(D12:D18) -> 900 | E19: cn | H19: =SUM(H12:H18) -> 0 | I19: =SUM(I12:I18) -> 1050
B20: =B18+1 -> 46257 | C20: 0 | D20: 0 | I20: =H20-C20 -> 0
B21: =B20+1 -> 46258 | C21: 0 | D21: 0 | I21: =H21-C21 -> 0
B22: =B21+1 -> 46259 | C22: 0 | D22: 0 | I22: =H22-C22 -> 0
B23: =B22+1 -> 46260 | C23: -900 | D23: 620 | E23: cn | I23: =H23-C23 -> 900
B24: =B23+1 -> 46261 | C24: 0 | D24: 0 | I24: =H24-C24 -> 0
B25: =B24+1 -> 46262 | C25: 0 | D25: 0 | I25: =H25-C25 -> 0
B26: =B25+1 -> 46263 | C26: 0 | D26: 0 | I26: =H26-C26 -> 0
B27: Total Week | C27: =SUM(C20:C26) -> -900 | D27: =SUM(D20:D26) -> 620 | E27: cn | H27: =SUM(H20:H26) -> 0 | I27: =SUM(I20:I26) -> 900
B28: =B26+1 -> 46264 | C28: 0 | D28: 0 | I28: =H28-C28 -> 0
B29: =B28+1 -> 46265 | C29: 0 | D29: 0 | I29: =H29-C29 -> 0
B30: =B29+1 -> 46266 | C30: -620 | D30: 450 | E30: cn | I30: =H30-C30 -> 620
B31: =B30+1 -> 46267 | C31: 0 | D31: 0 | I31: =H31-C31 -> 0
B32: =B31+1 -> 46268 | C32: 0 | D32: 0 | I32: =H32-C32 -> 0
B33: =B32+1 -> 46269 | C33: 0 | D33: 0 | I33: =H33-C33 -> 0
B34: =B33+1 -> 46270 | C34: -450 | D34: 0 | E34: cn | I34: =H34-C34 -> 450
B35: Total Week | C35: =SUM(C28:C34) -> -1070 | D35: =SUM(D28:D34) -> 450 | E35: cn | H35: =SUM(H28:H34) -> 0 | I35: =SUM(I28:I34) -> 1070
B36: Total Period | C36: =SUM(C35+C27+C19+C11) -> -3020 | D36: =SUM(D35+D27+D19+D11) -> 3020 | E36: cn | H36: =SUM(H35+H27+H19+H11) -> 0 | I36: =SUM(I35+I27+I19+I11) -> 3020
B37: Period Activity | C37: 0 | H37: =I36+H36 -> 3020 | I37: =J36+I36 -> 3020
C38: =B34+1 -> 46271 | D38: After Period Close
B39: Ending Period Count of Amount on hand | C39: 0 | E39: cn
B41: Number of Cash Drawers | C41: 2
...

Sheet CR
C1: Carson
C2: Per Restaurant
C3: Chage Order Deposits | D3: Change Order Received | E3: Initials | F3: Comments | H3: Cash over/ (Short) per R365 Flash report | I3: True Over/ (Short)
B4: =Control!$B$3 -> 46243 | C4: 0 | D4: 0 | H4: 31.2 | I4: =H4-C4 -> 31.2
B5: =B4+1 -> 46244 | C5: 0 | D5: 0 | H5: 1081.44 | I5: =H5-C5 -> 1081.44
B6: =B5+1 -> 46245 | C6: 0 | D6: 0 | H6: -137.56 | I6: =H6-C6 -> -137.56
B7: =B6+1 -> 46246 | C7: 0 | D7: 0 | H7: -8.59 | I7: =H7-C7 -> -8.59
B8: =B7+1 -> 46247 | C8: 0 | D8: 0 | H8: 25.98 | I8: =H8-C8 -> 25.98
B9: =B8+1 -> 46248 | C9: 0 | D9: 0 | H9: -23.91 | I9: =H9-C9 -> -23.91
B10: =B9+1 -> 46249 | C10: 0 | D10: 0 | H10: -18.19 | I10: =H10-C10 -> -18.19
B11: Total Week | C11: =SUM(C4:C10) -> 0 | D11: =SUM(D4:D10) -> 0 | H11: =SUM(H4:H10) -> 950.37 | I11: =SUM(I4:I10) -> 950.37
B12: =B10+1 -> 46250 | C12: 0 | D12: 0 | H12: 200.32 | I12: =H12-C12 -> 200.32
B13: =B12+1 -> 46251 | C13: 0 | D13: 0 | H13: -189.65 | I13: =H13-C13 -> -189.65
B14: =B13+1 -> 46252 | C14: 0 | D14: 0 | H14: -22.4 | I14: =H14-C14 -> -22.4
B15: =B14+1 -> 46253 | C15: 0 | D15: 0 | H15: -21.06 | I15: =H15-C15 -> -21.06
B16: =B15+1 -> 46254 | C16: 0 | D16: 0 | H16: -0.46 | I16: =H16-C16 -> -0.46
B17: =B16+1 -> 46255 | C17: 0 | D17: 0 | H17: -34.57 | I17: =H17-C17 -> -34.57
B18: =B17+1 -> 46256 | C18: 0 | D18: 0 | H18: -37.49 | I18: =H18-C18 -> -37.49
B19: Total Week | C19: =SUM(C12:C18) -> 0 | D19: =SUM(D12:D18) -> 0 | H19: =SUM(H12:H18) -> -105.31 | I19: =SUM(I12:I18) -> -105.31
B20: =B18+1 -> 46257 | C20: 0 | D20: 0 | H20: -106 | I20: =H20-C20 -> -106
B21: =B20+1 -> 46258 | C21: 0 | D21: 0 | H21: 4 | I21: =H21-C21 -> 4
B22: =B21+1 -> 46259 | C22: 1400 | D22: 700 | E22: SM,NJ,TB | F22: Paid $ 1,400 Change Order /Recieved $700.00 | H22: 680 | I22: =H22-C22 -> -720
B23: =B22+1 -> 46260 | C23: 0 | H23: -9 | I23: =H23-C23 -> -9
B24: =B23+1 -> 46261 | C24: 0 | D24: 0 | H24: 19 | I24: =H24-C24 -> 19
B25: =B24+1 -> 46262 | C25: 0 | D25: 0 | H25: -49 | I25: =H25-C25 -> -49
B26: =B25+1 -> 46263 | C26: 0 | D26: 0 | H26: 13 | I26: =H26-C26 -> 13
B27: Total Week | C27: =SUM(C20:C26) -> 1400 | D27: =SUM(D20:D26) -> 700 | H27: =SUM(H20:H26) -> 552 | I27: =SUM(I20:I26) -> -848
B28: =B26+1 -> 46264 | C28: 0 | D28: 0 | H28: -1767 | I28: =H28-C28 -> -1767
B29: =B28+1 -> 46265 | C29: 0 | D29: 0 | H29: -1205 | I29: =H29-C29 -> -1205
B30: =B29+1 -> 46266 | C30: 700 | D30: 1500 | E30: SM,NJ,TB | F30: Paid$700.00 Change Order/Recieved $1,500 | H30: 720 | I30: =H30-C30 -> 20
B31: =B30+1 -> 46267 | C31: 0 | D31: 0 | H31: -21 | I31: =H31-C31 -> -21
B32: =B31+1 -> 46268 | C32: 0 | D32: 0 | H32: -798 | I32: =H32-C32 -> -798
B33: =B32+1 -> 46269 | C33: 0 | D33: 0 | H33: 0 | I33: =H33-C33 -> 0
B34: =B33+1 -> 46270 | C34: 0 | D34: 0 | H34: -20 | I34: =H34-C34 -> -20
B35: Total Week | C35: =SUM(C28:C34) -> 700 | D35: =SUM(D28:D34) -> 1500 | H35: =SUM(H28:H34) -> -3091 | I35: =SUM(I28:I34) -> -3791
B36: Total Period | C36: =SUM(C35+C27+C19+C11) -> 2100 | D36: =SUM(D35+D27+D19+D11) -> 2200 | H36: =SUM(H35+H27+H19+H11) -> -1693.94 | I36: =SUM(I35+I27+I19+I11) -> -3793.94
B37: Period Activity | C37: =D36+C36 -> 4300 | H37: =I36+H36 -> -5487.88 | I37: =J36+I36 -> -3793.94
C38: =B34+1 -> 46271 | D38: After Period Close
B39: Ending Period Count of Amount on hand | C39: 1500 | E39: NJ
B41: Number of Cash Drawers | C41: 2
...

Sheet DN
C1: Downey
C2: Per Restaurant
C3: Chage Order Deposits (Positive amount) | D3: Change Order Received | E3: Initials | F3: Comments | H3: Cash over/ (Short) per R365 Flash report | I3: True Over/ (Short)
B4: =Control!$B$3 -> 46243 | C4: 1000 | D4: 0 | E4: DJS | I4: =H4-C4 -> -1000
B5: =B4+1 -> 46244 | C5: 0 | D5: 0 | I5: =H5-C5 -> 0
B6: =B5+1 -> 46245 | C6: 0 | D6: 0 | I6: =H6-C6 -> 0
B7: =B6+1 -> 46246 | C7: 1000 | D7: 0 | E7: DJS | I7: =H7-C7 -> -1000
B8: =B7+1 -> 46247 | C8: 0 | D8: 3000 | E8: DJS | I8: =H8-C8 -> 0
B9: =B8+1 -> 46248 | C9: 0 | D9: 0 | I9: =H9-C9 -> 0
B10: =B9+1 -> 46249 | C10: 0 | D10: 0 | I10: =H10-C10 -> 0
B11: Total Week | C11: =SUM(C4:C10) -> 2000 | D11: =SUM(D4:D10) -> 3000 | H11: =SUM(H4:H10) -> 0 | I11: =SUM(I4:I10) -> -2000
B12: =B10+1 -> 46250 | C12: 1000 | D12: 0 | I12: =H12-C12 -> -1000
B13: =B12+1 -> 46251 | C13: 1000 | D13: 0 | E13: DJS | I13: =H13-C13 -> -1000
B14: =B13+1 -> 46252 | C14: 0 | D14: 0 | I14: =H14-C14 -> 0
B15: =B14+1 -> 46253 | C15: 0 | D15: 0 | I15: =H15-C15 -> 0
B16: =B15+1 -> 46254 | C16: 0 | D16: 0 | I16: =H16-C16 -> 0
B17: =B16+1 -> 46255 | C17: 0 | D17: 0 | I17: =H17-C17 -> 0
B18: =B17+1 -> 46256 | C18: 0 | D18: 0 | I18: =H18-C18 -> 0
B19: Total Week | C19: =SUM(C12:C18) -> 2000 | D19: =SUM(D12:D18) -> 0 | H19: =SUM(H12:H18) -> 0 | I19: =SUM(I12:I18) -> -2000
B20: =B18+1 -> 46257 | C20: 1000 | D20: 0 | E20: DJS | I20: =H20-C20 -> -1000
B21: =B20+1 -> 46258 | C21: 0 | D21: 0 | E21: DB | I21: =H21-C21 -> 0
B22: =B21+1 -> 46259 | C22: 0 | D22: 0 | E22: DB | I22: =H22-C22 -> 0
B23: =B22+1 -> 46260 | C23: 990 | D23: 2990 | E23: DB | H23: 1011 | I23: =H23-C23 -> 21
B24: =B23+1 -> 46261 | C24: 0 | D24: 0 | E24: djs | H24: 15 | I24: =H24-C24 -> 15
B25: =B24+1 -> 46262 | C25: 0 | D25: 0 | E25: djs | H25: 12 | I25: =H25-C25 -> 12
B26: =B25+1 -> 46263 | C26: 1000 | D26: 0 | E26: djs | H26: 1030 | I26: =H26-C26 -> 30
B27: Total Week | C27: =SUM(C20:C26) -> 2990 | D27: =SUM(D20:D26) -> 2990 | H27: =SUM(H20:H26) -> 2068 | I27: =SUM(I20:I26) -> -922
B28: =B26+1 -> 46264 | C28: 1000 | D28: 0 | E28: djs | H28: 19 | I28: =H28-C28 -> -981
B29: =B28+1 -> 46265 | C29: 0 | D29: 0 | E29: DB | H29: 3 | I29: =H29-C29 -> 3
B30: =B29+1 -> 46266 | C30: 0 | D30: 3000 | E30: djs | F30: Ordered on Sun 8.30.26 | H30: 3007 | I30: =H30-C30 -> 3007
B31: =B30+1 -> 46267 | C31: 0 | D31: 0 | E31: DB | H31: 17 | I31: =H31-C31 -> 17
B32: =B31+1 -> 46268 | C32: 1000 | D32: 0 | E32: DJS | H32: 1012 | I32: =H32-C32 -> 12
B33: =B32+1 -> 46269 | C33: 0 | D33: 0 | E33: djs | H33: 14 | I33: =H33-C33 -> 14
B34: =B33+1 -> 46270 | C34: 0 | D34: 0 | E34: djs | H34: 8 | I34: =H34-C34 -> 8
B35: Total Week | C35: =SUM(C28:C34) -> 2000 | D35: =SUM(D28:D34) -> 3000 | H35: =SUM(H28:H34) -> 4080 | I35: =SUM(I28:I34) -> 2080
B36: Total Period | C36: =SUM(C35+C27+C19+C11) -> 8990 | D36: =SUM(D35+D27+D19+D11) -> 8990 | H36: =SUM(H35+H27+H19+H11) -> 6148 | I36: =SUM(I35+I27+I19+I11) -> -2842
B37: Period Activity | C37: =D36+C36 -> 17980 | H37: =I36+H36 -> 3306 | I37: =J36+I36 -> -2842
C38: =B34+1 -> 46271 | D38: After Period Close
B39: Ending Period Count of Amount on hand | C39: 4000
B41: Number of Cash Drawers | C41: 2
...

Sheet EM
C1: El Monte
C2: Per Restaurant
C3: Chage Order Deposits | D3: Change Order Received | E3: Initials | F3: Comments | H3: Cash over/ (Short) per R365 Flash report | I3: True Over/ (Short)
B4: =Control!$B$3 -> 46243 | C4: 0 | E4: CV | H4: 16.57 | I4: =H4-C4 -> 16.57
B5: =B4+1 -> 46244 | C5: 0 | D5: 0 | E5: CV | H5: 12.63 | I5: =H5-C5 -> 12.63
B6: =B5+1 -> 46245 | C6: 0 | D6: 0 | E6: CV | H6: -3.06 | I6: =H6-C6 -> -3.06
B7: =B6+1 -> 46246 | C7: 0 | D7: 0 | E7: CV | H7: -4.55 | I7: =H7-C7 -> -4.55
B8: =B7+1 -> 46247 | C8: 0 | E8: CV | H8: 51.44 | I8: =H8-C8 -> 51.44
B9: =B8+1 -> 46248 | C9: 0 | D9: 0 | E9: CV | H9: -45.54 | I9: =H9-C9 -> -45.54
B10: =B9+1 -> 46249 | C10: 0 | D10: 0 | E10: CV | H10: 14.9 | I10: =H10-C10 -> 14.9
B11: Total Week | C11: =SUM(C4:C10) -> 0 | D11: =SUM(D4:D10) -> 0 | H11: =SUM(H4:H10) -> 42.39 | I11: =SUM(I4:I10) -> 42.39
B12: =B10+1 -> 46250 | C12: 0 | D12: 0 | E12: CV | H12: -4 | I12: =H12-C12 -> -4
B13: =B12+1 -> 46251 | C13: 0 | D13: 0 | E13: CV | H13: -118.41 | I13: =H13-C13 -> -118.41
B14: =B13+1 -> 46252 | C14: 0 | D14: 0 | E14: CV | H14: 132.6 | I14: =H14-C14 -> 132.6
B15: =B14+1 -> 46253 | C15: 0 | D15: 1500 | E15: CV | H15: -1489.72 | I15: =H15-C15 -> -1489.72
B16: =B15+1 -> 46254 | C16: 1495 | E16: CV | H16: -17.93 | I16: =H16-C16 -> -1512.93
B17: =B16+1 -> 46255 | C17: 0 | D17: 0 | E17: CV | H17: 110.74 | I17: =H17-C17 -> 110.74
B18: =B17+1 -> 46256 | C18: 0 | D18: 0 | E18: CV | H18: -95.72 | I18: =H18-C18 -> -95.72
B19: Total Week | C19: =SUM(C12:C18) -> 1495 | D19: =SUM(D12:D18) -> 1500 | H19: =SUM(H12:H18) -> -1482.44 | I19: =SUM(I12:I18) -> -2977.44
B20: =B18+1 -> 46257 | C20: 0 | D20: 0 | E20: CV | H20: 16.22 | I20: =H20-C20 -> 16.22
B21: =B20+1 -> 46258 | C21: 0 | D21: 0 | E21: CV | H21: 0.65 | I21: =H21-C21 -> 0.65
B22: =B21+1 -> 46259 | C22: 0 | D22: 0 | E22: CV | H22: 7.78 | I22: =H22-C22 -> 7.78
B23: =B22+1 -> 46260 | C23: 0 | D23: 0 | E23: CV | H23: -1.2 | I23: =H23-C23 -> -1.2
B24: =B23+1 -> 46261 | C24: 0 | D24: 0 | E24: CV | H24: -2.21 | I24: =H24-C24 -> -2.21
B25: =B24+1 -> 46262 | C25: 0 | D25: 0 | E25: CV | H25: -22 | I25: =H25-C25 -> -22
B26: =B25+1 -> 46263 | C26: 0 | D26: 1655 | E26: CV | H26: 13.2 | I26: =H26-C26 -> 13.2
B27: Total Week | C27: =SUM(C20:C26) -> 0 | D27: =SUM(D20:D26) -> 1655 | E27: CV | H27: =SUM(H20:H26) -> 12.44 | I27: =SUM(I20:I26) -> 12.44
B28: =B26+1 -> 46264 | C28: 0 | D28: 0 | E28: CV | H28: -3107.7 | I28: =H28-C28 -> -3107.7
B29: =B28+1 -> 46265 | C29: 0 | D29: 0 | E29: CV | H29: 59.91 | I29: =H29-C29 -> 59.91
B30: =B29+1 -> 46266 | C30: 0 | D30: 0 | E30: CV | H30: 10 | I30: =H30-C30 -> 10
B31: =B30+1 -> 46267 | C31: 0 | D31: 0 | E31: CV | H31: 17 | I31: =H31-C31 -> 17
B32: =B31+1 -> 46268 | D32: 0 | E32: CV | H32: 1522 | I32: =H32-C32 -> 1522
B33: =B32+1 -> 46269 | C33: 1500 | D33: 1660 | E33: CV | H33: -185 | I33: =H33-C33 -> -1685
B34: =B33+1 -> 46270 | C34: 0 | E34: CV | H34: 4.59 | I34: =H34-C34 -> 4.59
B35: Total Week | C35: =SUM(C28:C34) -> 1500 | D35: =SUM(D28:D34) -> 1660 | H35: =SUM(H28:H34) -> -1679.2 | I35: =SUM(I28:I34) -> -3179.2
B36: Total Period | C36: =SUM(C35+C27+C19+C11) -> 2995 | D36: =SUM(D35+D27+D19+D11) -> 4815 | H36: =SUM(H35+H27+H19+H11) -> -3106.81 | I36: =SUM(I35+I27+I19+I11) -> -6101.81
B37: Period Activity | C37: =D36+C36 -> 7810 | H37: =I36+H36 -> -9208.62 | I37: =J36+I36 -> -6101.81
C38: =B34+1 -> 46271 | D38: After Period Close
B39: Ending Period Count of Amount on hand
B41: Number of Cash Drawers | C41: 1
...

Sheet HW
C1: Hollywood
C2: Per Restaurant
C3: Chage Order Deposits | D3: Change Order Received | E3: Initials | F3: Comments | H3: Cash over/ (Short) per R365 Flash report | I3: True Over/ (Short)
B4: =Control!$B$3 -> 46243 | C4: 0 | D4: 0 | E4: RR | H4: -111 | I4: =H4-C4 -> -111
B5: =B4+1 -> 46244 | C5: 0 | D5: 0 | E5: RR | H5: -7 | I5: =H5-C5 -> -7
B6: =B5+1 -> 46245 | D6: 1000 | E6: RR | H6: 43 | I6: =H6-C6 -> 43
B7: =B6+1 -> 46246 | C7: -500 | E7: RR | H7: 6 | I7: =H7-C7 -> 506
B8: =B7+1 -> 46247 | C8: 0 | D8: 0 | E8: RR | H8: -9 | I8: =H8-C8 -> -9
B9: =B8+1 -> 46248 | D9: 980 | E9: RR | H9: -1001 | I9: =H9-C9 -> -1001
B10: =B9+1 -> 46249 | C10: -500 | D10: 500 | E10: RR | H10: 941 | I10: =H10-C10 -> 1441
B11: Total Week | C11: =SUM(C4:C10) -> -1000 | D11: =SUM(D4:D10) -> 2480 | E11: RR | H11: =SUM(H4:H10) -> -138 | I11: =SUM(I4:I10) -> 862
B12: =B10+1 -> 46250 | C12: 0 | D12: 0 | E12: RR | H12: 2 | I12: =H12-C12 -> 2
B13: =B12+1 -> 46251 | C13: 0 | D13: 0 | E13: RR | H13: -1 | I13: =H13-C13 -> -1
B14: =B13+1 -> 46252 | C14: 0 | D14: 0 | E14: RR | H14: -34 | I14: =H14-C14 -> -34
B15: =B14+1 -> 46253 | C15: -1000 | E15: RR | H15: 2038 | I15: =H15-C15 -> 3038
B16: =B15+1 -> 46254 | C16: 0 | D16: 0 | E16: RR | H16: -16 | I16: =H16-C16 -> -16
B17: =B16+1 -> 46255 | D17: 1600 | E17: RR | H17: -1591 | I17: =H17-C17 -> -1591
B18: =B17+1 -> 46256 | C18: 0 | D18: 0 | E18: RR | H18: -38 | I18: =H18-C18 -> -38
B19: Total Week | C19: =SUM(C12:C18) -> -1000 | D19: =SUM(D12:D18) -> 1600 | E19: RR | H19: =SUM(H12:H18) -> 360 | I19: =SUM(I12:I18) -> 1360
B20: =B18+1 -> 46257 | C20: 0 | D20: 0 | E20: RR | H20: -78 | I20: =H20-C20 -> -78
B21: =B20+1 -> 46258 | C21: 0 | D21: 0 | E21: RR | H21: 14 | I21: =H21-C21 -> 14
B22: =B21+1 -> 46259 | C22: 0 | D22: 0 | E22: RR | H22: -7 | I22: =H22-C22 -> -7
B23: =B22+1 -> 46260 | C23: -500 | E23: RR | H23: 1008 | I23: =H23-C23 -> 1508
B24: =B23+1 -> 46261 | C24: 0 | D24: 0 | E24: RR | H24: -1 | I24: =H24-C24 -> -1
B25: =B24+1 -> 46262 | C25: 0 | D25: 980 | E25: RR | H25: -1 | I25: =H25-C25 -> -1
B26: =B25+1 -> 46263 | C26: 0 | D26: 0 | E26: RR | H26: -7 | I26: =H26-C26 -> -7
B27: Total Week | C27: =SUM(C20:C26) -> -500 | D27: =SUM(D20:D26) -> 980 | E27: RR | H27: =SUM(H20:H26) -> 928 | I27: =SUM(I20:I26) -> 1428
B28: =B26+1 -> 46264 | C28: 0 | D28: 0 | E28: RR | H28: -193 | I28: =H28-C28 -> -193
B29: =B28+1 -> 46265 | C29: 0 | D29: 0 | E29: RR | H29: -144 | I29: =H29-C29 -> -144
B30: =B29+1 -> 46266 | C30: 0 | D30: 0 | E30: RR | H30: -1 | I30: =H30-C30 -> -1
B31: =B30+1 -> 46267 | C31: -500 | D31: 0 | E31: RR | H31: 308 | I31: =H31-C31 -> 808
B32: =B31+1 -> 46268 | C32: 0 | D32: 0 | E32: RR | H32: 208 | I32: =H32-C32 -> 208
B33: =B32+1 -> 46269 | C33: 0 | D33: 0 | E33: RR | H33: -35 | I33: =H33-C33 -> -35
B34: =B33+1 -> 46270 | C34: -500 | D34: 0 | E34: RR | H34: 506 | I34: =H34-C34 -> 1006
B35: Total Week | C35: =SUM(C28:C34) -> -1000 | D35: =SUM(D28:D34) -> 0 | H35: =SUM(H28:H34) -> 649 | I35: =SUM(I28:I34) -> 1649
B36: Total Period | C36: =SUM(C35+C27+C19+C11) -> -3500 | D36: =SUM(D35+D27+D19+D11) -> 5060 | H36: =SUM(H35+H27+H19+H11) -> 1799 | I36: =SUM(I35+I27+I19+I11) -> 5299
B37: Period Activity | C37: =D36+C36 -> 1560 | H37: =I36+H36 -> 7098 | I37: =J36+I36 -> 5299
C38: =B34+1 -> 46271 | D38: After Period Close
B39: Ending Period Count of Amopunt on hand | C39: 3080 | E39: RR JA
B41: Number of Cash Drawers | C41: 2
...

Sheet HB
C1: Huntington Beach
C2: Per Restaurant
C3: Chage Order Deposits | D3: Change Order Received | E3: Initials | F3: Comments | H3: Cash over/ (Short) per R365 Flash report | I3: True Over/ (Short)
B4: =Control!$B$3 -> 46243 | C4: 0 | D4: 0 | I4: =H4-C4 -> 0
B5: =B4+1 -> 46244 | C5: 0 | D5: 0 | I5: =H5-C5 -> 0
B6: =B5+1 -> 46245 | C6: 0 | D6: 0 | I6: =H6-C6 -> 0
B7: =B6+1 -> 46246 | C7: 0 | D7: 1120 | E7: CM/JG | F7: We will pay back this money as soon as we get our next delivery | I7: =H7-C7 -> 0
B8: =B7+1 -> 46247 | C8: 0 | D8: 0 | I8: =H8-C8 -> 0
B9: =B8+1 -> 46248 | C9: 0 | D9: 0 | I9: =H9-C9 -> 0
B10: =B9+1 -> 46249 | C10: 0 | D10: 0 | I10: =H10-C10 -> 0
B11: Total Week | C11: =SUM(C4:C10) -> 0 | D11: =SUM(D4:D10) -> 1120 | H11: =SUM(H4:H10) -> 0 | I11: =SUM(I4:I10) -> 0
B12: =B10+1 -> 46250 | C12: 0 | D12: 0 | I12: =H12-C12 -> 0
B13: =B12+1 -> 46251 | C13: 0 | D13: 0 | I13: =H13-C13 -> 0
B14: =B13+1 -> 46252 | C14: 0 | D14: 0 | I14: =H14-C14 -> 0
B15: =B14+1 -> 46253 | C15: 0 | D15: 0 | I15: =H15-C15 -> 0
B16: =B15+1 -> 46254 | C16: 0 | D16: 0 | I16: =H16-C16 -> 0
B17: =B16+1 -> 46255 | C17: 0 | D17: 0 | I17: =H17-C17 -> 0
B18: =B17+1 -> 46256 | C18: 0 | D18: 0 | I18: =H18-C18 -> 0
B19: Total Week | C19: =SUM(C12:C18) -> 0 | D19: =SUM(D12:D18) -> 0 | H19: =SUM(H12:H18) -> 0 | I19: =SUM(I12:I18) -> 0
B20: =B18+1 -> 46257 | C20: 0 | D20: 0 | I20: =H20-C20 -> 0
B21: =B20+1 -> 46258 | C21: 0 | D21: 0 | I21: =H21-C21 -> 0
B22: =B21+1 -> 46259 | C22: 0 | D22: 0 | I22: =H22-C22 -> 0
B23: =B22+1 -> 46260 | C23: 0 | D23: 0 | I23: =H23-C23 -> 0
B24: =B23+1 -> 46261 | C24: 0 | D24: 0 | I24: =H24-C24 -> 0
B25: =B24+1 -> 46262 | C25: 0 | D25: 0 | I25: =H25-C25 -> 0
B26: =B25+1 -> 46263 | C26: 0 | D26: 0 | I26: =H26-C26 -> 0
B27: Total Week | C27: =SUM(C20:C26) -> 0 | D27: =SUM(D20:D26) -> 0 | H27: =SUM(H20:H26) -> 0 | I27: =SUM(I20:I26) -> 0
B28: =B26+1 -> 46264 | C28: 0 | D28: 0 | E28: FM | H28: -43.61 | I28: =H28-C28 -> -43.61
B29: =B28+1 -> 46265 | C29: 0 | D29: 0 | E29: JG | H29: 16.88 | I29: =H29-C29 -> 16.88
B30: =B29+1 -> 46266 | C30: 0 | D30: 0 | E30: JG | H30: -3.01 | I30: =H30-C30 -> -3.01
B31: =B30+1 -> 46267 | C31: 0 | D31: 0 | E31: FM | H31: -28.16 | I31: =H31-C31 -> -28.16
B32: =B31+1 -> 46268 | C32: 0 | D32: 0 | E32: CM | H32: -8.4 | I32: =H32-C32 -> -8.4
B33: =B32+1 -> 46269 | C33: 0 | D33: 0 | E33: CM | H33: 39.74 | I33: =H33-C33 -> 39.74
B34: =B33+1 -> 46270 | C34: 0 | D34: 0 | E34: CM | H34: -13.11 | I34: =H34-C34 -> -13.11
B35: Total Week | C35: =SUM(C28:C34) -> 0 | D35: =SUM(D28:D34) -> 0 | H35: =SUM(H28:H34) -> -39.67 | I35: =SUM(I28:I34) -> -39.67
B36: Total Period | C36: =SUM(C35+C27+C19+C11) -> 0 | D36: =SUM(D35+D27+D19+D11) -> 1120 | H36: =SUM(H35+H27+H19+H11) -> -39.67 | I36: =SUM(I35+I27+I19+I11) -> -39.67
B37: Period Activity | C37: =D36+C36 -> 1120 | H37: =I36+H36 -> -79.34 | I37: =J36+I36 -> -39.67
C38: =B34+1 -> 46271 | D38: After Period Close
B39: Ending Period Count of Amount on hand | C39: 1120 | E39: CM/JG | F39: We will pay back this money as soon as we get our next delivery
B41: Number of Cash Drawers | C41: 2
...

Sheet IG
C1: Inglewood
C2: Per Restaurant
C3: Chage Order Deposits | D3: Change Order Received | E3: Initials | F3: Comments | H3: Cash over/ (Short) per R365 Flash report | I3: True Over/ (Short)
B4: =Control!$B$3 -> 46243 | C4: 0 | D4: 4095 | E4: MH | F4: Bank Balance of $4095.00( no money was received on the week 08/09 | H4: =C4 -> 0 | I4: =H4-C4 -> 0
B5: =B4+1 -> 46244 | C5: 0 | D5: 0 | F5: till 08/15 see full report. | H5: =C5 -> 0 | I5: =H5-C5 -> 0
B6: =B5+1 -> 46245 | C6: 0 | D6: 0 | H6: =C6 -> 0 | I6: =H6-C6 -> 0
B7: =B6+1 -> 46246 | C7: 0 | D7: 0 | H7: =C7 -> 0 | I7: =H7-C7 -> 0
B8: =B7+1 -> 46247 | C8: 0 | D8: 0 | H8: =C8 -> 0 | I8: =H8-C8 -> 0
B9: =B8+1 -> 46248 | C9: 0 | D9: 0 | H9: =C9 -> 0 | I9: =H9-C9 -> 0
B10: =B9+1 -> 46249 | C10: 0 | D10: 0 | H10: =C10 -> 0 | I10: =H10-C10 -> 0
B11: Total Week | C11: =SUM(C4:C10) -> 0 | D11: =SUM(D4:D10) -> 4095 | H11: =SUM(H4:H10) -> 0 | I11: =SUM(I4:I10) -> 0
B12: =B10+1 -> 46250 | C12: 0 | D12: 0 | H12: =C12 -> 0 | I12: =H12-C12 -> 0
B13: =B12+1 -> 46251 | C13: 0 | D13: 0 | H13: =C13 -> 0 | I13: =H13-C13 -> 0
B14: =B13+1 -> 46252 | C14: 0 | D14: 0 | H14: =C14 -> 0 | I14: =H14-C14 -> 0
B15: =B14+1 -> 46253 | C15: 0 | D15: 0 | H15: =C15 -> 0 | I15: =H15-C15 -> 0
B16: =B15+1 -> 46254 | C16: 0 | D16: 0 | H16: =C16 -> 0 | I16: =H16-C16 -> 0
B17: =B16+1 -> 46255 | C17: 1695 | D17: 0 | E17: MH | H17: =C17 -> 1695 | I17: =H17-C17 -> 0
B18: =B17+1 -> 46256 | C18: 0 | D18: 0 | H18: =C18 -> 0 | I18: =H18-C18 -> 0
B19: Total Week | C19: =SUM(C12:C18) -> 1695 | D19: =SUM(D12:D18) -> 0 | H19: =SUM(H12:H18) -> 1695 | I19: =SUM(I12:I18) -> 0
B20: =B18+1 -> 46257 | C20: 0 | D20: 0 | H20: =C20 -> 0 | I20: =H20-C20 -> 0
B21: =B20+1 -> 46258 | C21: 0 | D21: 1500 | E21: GG | H21: =C21 -> 0 | I21: =H21-C21 -> 0
B22: =B21+1 -> 46259 | C22: 0 | D22: 0 | H22: =C22 -> 0 | I22: =H22-C22 -> 0
B23: =B22+1 -> 46260 | C23: 2000 | D23: 0 | H23: =C23 -> 2000 | I23: =H23-C23 -> 0
B24: =B23+1 -> 46261 | C24: 0 | D24: 0 | H24: =C24 -> 0 | I24: =H24-C24 -> 0
B25: =B24+1 -> 46262 | C25: 0 | D25: 0 | H25: =C25 -> 0 | I25: =H25-C25 -> 0
B26: =B25+1 -> 46263 | C26: 400 | D26: 0 | H26: =C26 -> 400 | I26: =H26-C26 -> 0
B27: Total Week | C27: =SUM(C20:C26) -> 2400 | D27: =SUM(D20:D26) -> 1500 | H27: =SUM(H20:H26) -> 2400 | I27: =SUM(I20:I26) -> 0
B28: =B26+1 -> 46264 | C28: 0 | D28: 0 | H28: =C28 -> 0 | I28: =H28-C28 -> 0
B29: =B28+1 -> 46265 | C29: 0 | D29: 0 | H29: =C29 -> 0 | I29: =H29-C29 -> 0
B30: =B29+1 -> 46266 | C30: 0 | D30: 2900 | E30: GG | H30: -35 | I30: =H30-C30 -> -35
B31: =B30+1 -> 46267 | C31: 0 | D31: 0 | H31: 109 | I31: =H31-C31 -> 109
B32: =B31+1 -> 46268 | C32: 0 | D32: 0 | H32: 2083 | I32: =H32-C32 -> 2083
B33: =B32+1 -> 46269 | C33: 0 | D33: 0 | H33: -21 | I33: =H33-C33 -> -21
B34: =B33+1 -> 46270 | C34: 0 | D34: 0 | H34: 71 | I34: =H34-C34 -> 71
B35: Total Week | C35: =SUM(C28:C34) -> 0 | D35: =SUM(D28:D34) -> 2900 | H35: =SUM(H28:H34) -> 2207 | I35: =SUM(I28:I34) -> 2207
B36: Total Period | C36: =SUM(C35+C27+C19+C11) -> 4095 | D36: =SUM(D35+D27+D19+D11) -> 8495 | H36: =SUM(H35+H27+H19+H11) -> 6302 | I36: =SUM(I35+I27+I19+I11) -> 2207
B37: Period Activity | C37: =D36+C36 -> 12590 | E37: MH | H37: =I36+H36 -> 8509 | I37: =J36+I36 -> 2207
C38: =B34+1 -> 46271 | D38: After Period Close
B39: Ending Period Count of Amount on hand | C39: 4400 | E39: MH
B41: Number of Cash Drawers | C41: 2
...

Sheet LC
C1: La Cienega
C2: Per Restaurant
C3: Chage Order Deposits | D3: Change Order Received | E3: Initials | F3: Comments | H3: Cash over/ (Short) per R365 Flash report | I3: True Over/ (Short)
B4: =Control!$B$3 -> 46243 | C4: 0 | D4: 0 | I4: =H4-C4 -> 0
B5: =B4+1 -> 46244 | C5: 0 | D5: 0 | I5: =H5-C5 -> 0
B6: =B5+1 -> 46245 | C6: 0 | D6: 0 | I6: =H6-C6 -> 0
B7: =B6+1 -> 46246 | C7: 0 | D7: 0 | I7: =H7-C7 -> 0
B8: =B7+1 -> 46247 | C8: 0 | D8: 0 | I8: =H8-C8 -> 0
B9: =B8+1 -> 46248 | C9: 2405 | D9: 2405 | E9: TS | F9: coin deposit recieved and drop | I9: =H9-C9 -> -2405
B10: =B9+1 -> 46249 | C10: 0 | D10: 0 | I10: =H10-C10 -> 0
B11: Total Week | C11: =SUM(C4:C10) -> 2405 | D11: =SUM(D4:D10) -> 2405 | E11: TS | H11: =SUM(H4:H10) -> 0 | I11: =SUM(I4:I10) -> -2405
B12: =B10+1 -> 46250 | C12: 0 | D12: 0 | E12: Tony S | I12: =H12-C12 -> 0
B13: =B12+1 -> 46251 | C13: 0 | D13: 0 | E13: Tony S | I13: =H13-C13 -> 0
B14: =B13+1 -> 46252 | C14: 0 | D14: 0 | E14: Tony S | I14: =H14-C14 -> 0
B15: =B14+1 -> 46253 | C15: 0 | D15: 0 | E15: Tony S | I15: =H15-C15 -> 0
B16: =B15+1 -> 46254 | C16: 1620 | D16: 1620 | E16: Tony S | F16: coin deposit recieved and drop | I16: =H16-C16 -> -1620
B17: =B16+1 -> 46255 | C17: 0 | D17: 0 | E17: Tony S | I17: =H17-C17 -> 0
B18: =B17+1 -> 46256 | C18: 0 | D18: 0 | E18: Tony S | I18: =H18-C18 -> 0
B19: Total Week | C19: =SUM(C12:C18) -> 1620 | D19: =SUM(D12:D18) -> 1620 | E19: Tony S | H19: =SUM(H12:H18) -> 0 | I19: =SUM(I12:I18) -> -1620
B20: =B18+1 -> 46257 | C20: 0 | D20: 0 | E20: Tony S | I20: =H20-C20 -> 0
B21: =B20+1 -> 46258 | C21: 0 | D21: 0 | E21: Tony S | I21: =H21-C21 -> 0
B22: =B21+1 -> 46259 | C22: 0 | D22: 0 | E22: Tony S | I22: =H22-C22 -> 0
B23: =B22+1 -> 46260 | C23: 0 | D23: 0 | E23: Tony S | I23: =H23-C23 -> 0
B24: =B23+1 -> 46261 | C24: 0 | D24: 0 | E24: Tony S | I24: =H24-C24 -> 0
B25: =B24+1 -> 46262 | C25: 0 | D25: 0 | E25: Tony S | I25: =H25-C25 -> 0
B26: =B25+1 -> 46263 | C26: 0 | D26: 0 | E26: Tony S | I26: =H26-C26 -> 0
B27: Total Week | C27: 0 | D27: 0 | E27: Tony S | H27: =SUM(H20:H26) -> 0 | I27: =SUM(I20:I26) -> 0
B28: =B26+1 -> 46264 | C28: 0 | D28: 0 | E28: Tony S | I28: =H28-C28 -> 0
B29: =B28+1 -> 46265 | C29: 2095 | D29: 2095 | E29: Tony S | F29: coin deposit recieved and drop | I29: =H29-C29 -> -2095
B30: =B29+1 -> 46266 | C30: 0 | D30: 0 | E30: Tony S | H30: -35 | I30: =H30-C30 -> -35
B31: =B30+1 -> 46267 | C31: 0 | D31: 0 | E31: Tony S | H31: 109 | I31: =H31-C31 -> 109
B32: =B31+1 -> 46268 | C32: 0 | D32: 0 | E32: Tony S | H32: 2083 | I32: =H32-C32 -> 2083
B33: =B32+1 -> 46269 | C33: 0 | D33: 0 | E33: Tony S | H33: -21 | I33: =H33-C33 -> -21
B34: =B33+1 -> 46270 | C34: 0 | D34: 0 | E34: Tony S | H34: 71 | I34: =H34-C34 -> 71
B35: Total Week | C35: =SUM(C28:C34) -> 2095 | D35: =SUM(D28:D34) -> 2095 | E35: Tony S | H35: =SUM(H28:H34) -> 2207 | I35: =SUM(I28:I34) -> 112
B36: Total Period | C36: =SUM(C35+C27+C19+C11) -> 6120 | D36: =SUM(D35+D27+D19+D11) -> 6120 | E36: Tony S | H36: =SUM(H35+H27+H19+H11) -> 2207 | I36: =SUM(I35+I27+I19+I11) -> -3913
B37: Period Activity | C37: =D36+C36 -> 12240 | E37: Tony S | H37: =I36+H36 -> -1706 | I37: =J36+I36 -> -3913
C38: =B34+1 -> 46271 | D38: After Period Close
B39: Ending Period Count of Amount on hand | C39: 2405 | E39: Tony D | F39: safe count recieved.
B41: Number of Cash Drawers | C41: 3
...

Sheet LK
C1: Lakewood
C2: Per Restaurant
C3: Chage Order Deposits | D3: Change Order Received | E3: Initials | F3: Comments | H3: Cash over/ (Short) per R365 Flash report | I3: True Over/ (Short)
B4: =Control!$B$3 -> 46243 | C4: 0 | D4: 0 | E4: ER | H4: 27 | I4: =H4-C4 -> 27
B5: =B4+1 -> 46244 | C5: 0 | D5: 0 | E5: ER | H5: 0 | I5: =H5-C5 -> 0
B6: =B5+1 -> 46245 | C6: 0 | D6: 0 | E6: ER | H6: -85 | I6: =H6-C6 -> -85
B7: =B6+1 -> 46246 | C7: 0 | D7: 0 | E7: ER | H7: 1086 | I7: =H7-C7 -> 1086
B8: =B7+1 -> 46247 | C8: 0 | D8: 0 | E8: ER | H8: -31 | I8: =H8-C8 -> -31
B9: =B8+1 -> 46248 | C9: 0 | D9: 0 | E9: ER | H9: 141 | I9: =H9-C9 -> 141
B10: =B9+1 -> 46249 | C10: 1105 | D10: 1105 | E10: ER | H10: 50 | I10: =H10-C10 -> -1055
B11: Total Week | C11: =SUM(C4:C10) -> 1105 | D11: =SUM(D4:D10) -> 1105 | H11: =SUM(H4:H10) -> 1188 | I11: =SUM(I4:I10) -> 83
B12: =B10+1 -> 46250 | C12: 0 | D12: 0 | E12: ER | H12: 52 | I12: =H12-C12 -> 52
B13: =B12+1 -> 46251 | C13: 0 | D13: 0 | E13: ER | H13: 3 | I13: =H13-C13 -> 3
B14: =B13+1 -> 46252 | C14: 0 | E14: ER | H14: 66 | I14: =H14-C14 -> 66
B15: =B14+1 -> 46253 | C15: 0 | D15: 0 | E15: ER | H15: 2148 | I15: =H15-C15 -> 2148
B16: =B15+1 -> 46254 | C16: 0 | D16: 0 | E16: ER | H16: 0 | I16: =H16-C16 -> 0
B17: =B16+1 -> 46255 | C17: 0 | D17: 0 | E17: ER | H17: 15 | I17: =H17-C17 -> 15
B18: =B17+1 -> 46256 | C18: 0 | D18: 0 | E18: ER | H18: -12 | I18: =H18-C18 -> -12
B19: Total Week | C19: =SUM(C12:C18) -> 0 | D19: =SUM(D12:D18) -> 0 | H19: =SUM(H12:H18) -> 2272 | I19: =SUM(I12:I18) -> 2272
B20: =B18+1 -> 46257 | C20: 0 | D20: 0 | H20: -15 | I20: =H20-C20 -> -15
B21: =B20+1 -> 46258 | C21: 0 | D21: 0 | H21: 3 | I21: =H21-C21 -> 3
B22: =B21+1 -> 46259 | C22: 0 | D22: 0 | H22: 17 | I22: =H22-C22 -> 17
B23: =B22+1 -> 46260 | C23: 1350 | D23: 1350 | H23: 947 | I23: =H23-C23 -> -403
B24: =B23+1 -> 46261 | C24: 0 | D24: 0 | H24: 38 | I24: =H24-C24 -> 38
B25: =B24+1 -> 46262 | C25: 0 | D25: 0 | H25: 92 | I25: =H25-C25 -> 92
B26: =B25+1 -> 46263 | C26: 0 | D26: 0 | H26: 285 | I26: =H26-C26 -> 285
B27: Total Week | C27: =SUM(C20:C26) -> 1350 | D27: =SUM(D20:D26) -> 1350 | H27: =SUM(H20:H26) -> 1367 | I27: =SUM(I20:I26) -> 17
B28: =B26+1 -> 46264 | C28: 0 | D28: 0 | E28: ER | H28: 3 | I28: =H28-C28 -> 3
B29: =B28+1 -> 46265 | C29: 0 | D29: 0 | E29: ER | H29: 4 | I29: =H29-C29 -> 4
B30: =B29+1 -> 46266 | C30: 0 | D30: 0 | E30: ER | H30: 37 | I30: =H30-C30 -> 37
B31: =B30+1 -> 46267 | C31: 0 | D31: 0 | E31: ER | H31: 990 | I31: =H31-C31 -> 990
B32: =B31+1 -> 46268 | C32: 0 | D32: 1225 | E32: ER | F32: Received change order | H32: 104 | I32: =H32-C32 -> 104
B33: =B32+1 -> 46269 | C33: 0 | E33: ER | H33: 24 | I33: =H33-C33 -> 24
B34: =B33+1 -> 46270 | D34: 0 | E34: ER | H34: 47 | I34: =H34-C34 -> 47
B35: Total Week | C35: =SUM(C28:C34) -> 0 | D35: =SUM(D28:D34) -> 1225 | H35: =SUM(H28:H34) -> 1209 | I35: =SUM(I28:I34) -> 1209
B36: Total Period | C36: =SUM(C35+C27+C19+C11) -> 2455 | D36: =SUM(D35+D27+D19+D11) -> 3680 | H36: =SUM(H35+H27+H19+H11) -> 6036 | I36: =SUM(I35+I27+I19+I11) -> 3581
B37: Period Activity | C37: =D36+C36 -> 6135 | H37: =I36+H36 -> 9617 | I37: =J36+I36 -> 3581
C38: =B34+1 -> 46271 | D38: After Period Close
B39: Ending Period Count of Amount on hand | C39: 1525
B41: Number of Cash Drawers | C41: 2
...

Sheet LV
C1: Las Vegas
C2: Per Restaurant
C3: Chage Order Deposits | D3: Change Order Received | E3: Initials | F3: Comments | H3: Cash over/ (Short) per R365 Flash report | I3: True Over/ (Short)
B4: =Control!$B$3 -> 46243 | C4: 0 | D4: 0 | I4: =H4-C4 -> 0
B5: =B4+1 -> 46244 | C5: 0 | D5: 0 | I5: =H5-C5 -> 0
B6: =B5+1 -> 46245 | C6: 0 | D6: 0 | I6: =H6-C6 -> 0
B7: =B6+1 -> 46246 | C7: 0 | D7: 0 | I7: =H7-C7 -> 0
B8: =B7+1 -> 46247 | C8: 0 | D8: 0 | I8: =H8-C8 -> 0
B9: =B8+1 -> 46248 | C9: 0 | D9: 0 | I9: =H9-C9 -> 0
B10: =B9+1 -> 46249 | C10: 700 | D10: 0 | E10: ADC HT | I10: =H10-C10 -> -700
B11: Total Week | C11: =SUM(C4:C10) -> 700 | D11: =SUM(D4:D10) -> 0 | E11: ADC HT | H11: =SUM(H4:H10) -> 0 | I11: =SUM(I4:I10) -> -700
B12: =B10+1 -> 46250 | C12: 0 | D12: 0 | I12: =H12-C12 -> 0
B13: =B12+1 -> 46251 | C13: 0 | D13: 0 | I13: =H13-C13 -> 0
B14: =B13+1 -> 46252 | C14: 0 | D14: 1570 | E14: ADC HT | I14: =H14-C14 -> 0
B15: =B14+1 -> 46253 | C15: 0 | D15: 0 | I15: =H15-C15 -> 0
B16: =B15+1 -> 46254 | C16: 800 | D16: 0 | E16: ADC HT | I16: =H16-C16 -> -800
B17: =B16+1 -> 46255 | C17: 0 | D17: 0 | I17: =H17-C17 -> 0
B18: =B17+1 -> 46256 | C18: 0 | D18: 0 | I18: =H18-C18 -> 0
B19: Total Week | C19: =SUM(C12:C18) -> 800 | D19: =SUM(D12:D18) -> 1570 | E19: ADC HT | H19: =SUM(H12:H18) -> 0 | I19: =SUM(I12:I18) -> -800
B20: =B18+1 -> 46257 | C20: 0 | D20: 0 | I20: =H20-C20 -> 0
B21: =B20+1 -> 46258 | C21: 0 | D21: 0 | I21: =H21-C21 -> 0
B22: =B21+1 -> 46259 | C22: 0 | D22: 0 | I22: =H22-C22 -> 0
B23: =B22+1 -> 46260 | C23: 0 | D23: 0 | I23: =H23-C23 -> 0
B24: =B23+1 -> 46261 | C24: 0 | D24: 0 | I24: =H24-C24 -> 0
B25: =B24+1 -> 46262 | C25: 0 | D25: 0 | I25: =H25-C25 -> 0
B26: =B25+1 -> 46263 | C26: 0 | D26: 0 | I26: =H26-C26 -> 0
B27: Total Week | C27: =SUM(C20:C26) -> 0 | D27: =SUM(D20:D26) -> 0 | H27: =SUM(H20:H26) -> 0 | I27: =SUM(I20:I26) -> 0
B28: =B26+1 -> 46264 | C28: 0 | D28: 0 | I28: =H28-C28 -> 0
B29: =B28+1 -> 46265 | C29: 0 | D29: 0 | I29: =H29-C29 -> 0
B30: =B29+1 -> 46266 | C30: 0 | D30: 0 | I30: =H30-C30 -> 0
B31: =B30+1 -> 46267 | C31: 0 | D31: 0 | I31: =H31-C31 -> 0
B32: =B31+1 -> 46268 | D32: 6850 | E32: ADC HT | F32: 5000 Prize Pool For Cash Grab A Cox | I32: =H32-C32 -> 0
B33: =B32+1 -> 46269 | C33: 870 | D33: 0 | E33: ADC HT | I33: =H33-C33 -> -870
B34: =B33+1 -> 46270 | C34: 0 | D34: 0 | I34: =H34-C34 -> 0
B35: Total Week | C35: =SUM(C28:C34) -> 870 | D35: =SUM(D28:D34) -> 6850 | E35: ADC HT | H35: =SUM(H28:H34) -> 0 | I35: =SUM(I28:I34) -> -870
B36: Total Period | C36: =SUM(C35+C27+C19+C11) -> 2370 | D36: =SUM(D35+D27+D19+D11) -> 8420 | E36: ADC HT | H36: =SUM(H35+H27+H19+H11) -> 0 | I36: =SUM(I35+I27+I19+I11) -> -2370
B37: Period Activity | C37: =D36+C36 -> 10790 | H37: =I36+H36 -> -2370 | I37: =J36+I36 -> -2370
C38: =B34+1 -> 46271 | D38: After Period Close
B39: Ending Period Count of Amount on hand | C39: 7550 | F39: ADC HT CG Verified by all managers
B41: Number of Cash Drawers | C41: 2
...

Sheet ON
C1: Ontario
C2: Per Restaurant
C3: Chage Order Deposits | D3: Change Order Received | E3: Initials | F3: Comments | H3: Cash over/ (Short) per R365 Flash report | I3: True Over/ (Short)
B4: =Control!$B$3 -> 46243 | C4: 0 | D4: 0 | I4: =H4-C4 -> 0
B5: =B4+1 -> 46244 | C5: -700 | F5: The payment in column c pays the outstanding balance at the end of Per08 | I5: =H5-C5 -> 700
B6: =B5+1 -> 46245 | C6: 0 | D6: 700 | I6: =H6-C6 -> 0
B7: =B6+1 -> 46246 | C7: 0 | D7: 0 | I7: =H7-C7 -> 0
B8: =B7+1 -> 46247 | C8: 0 | D8: 0 | I8: =H8-C8 -> 0
B9: =B8+1 -> 46248 | C9: 0 | D9: 0 | I9: =H9-C9 -> 0
B10: =B9+1 -> 46249 | C10: 0 | D10: 0 | I10: =H10-C10 -> 0
B11: Total Week | C11: =SUM(C4:C10) -> -700 | D11: =SUM(D4:D10) -> 700 | H11: =SUM(H4:H10) -> 0 | I11: =SUM(I4:I10) -> 700
B12: =B10+1 -> 46250 | C12: 0 | D12: 0 | I12: =H12-C12 -> 0
B13: =B12+1 -> 46251 | C13: 0 | D13: 0 | I13: =H13-C13 -> 0
B14: =B13+1 -> 46252 | C14: 0 | D14: 0 | I14: =H14-C14 -> 0
B15: =B14+1 -> 46253 | C15: 0 | D15: 0 | I15: =H15-C15 -> 0
B16: =B15+1 -> 46254 | C16: 0 | D16: 0 | I16: =H16-C16 -> 0
B17: =B16+1 -> 46255 | C17: 0 | D17: 0 | I17: =H17-C17 -> 0
B18: =B17+1 -> 46256 | C18: 0 | D18: 0 | I18: =H18-C18 -> 0
B19: Total Week | C19: =SUM(C12:C18) -> 0 | D19: =SUM(D12:D18) -> 0 | H19: =SUM(H12:H18) -> 0 | I19: =SUM(I12:I18) -> 0
B20: =B18+1 -> 46257 | C20: -700 | D20: 0 | I20: =H20-C20 -> 700
B21: =B20+1 -> 46258 | C21: 0 | D21: 0 | I21: =H21-C21 -> 0
B22: =B21+1 -> 46259 | C22: 0 | D22: 700 | I22: =H22-C22 -> 0
B23: =B22+1 -> 46260 | C23: 0 | D23: 0 | I23: =H23-C23 -> 0
B24: =B23+1 -> 46261 | C24: 0 | D24: 0 | I24: =H24-C24 -> 0
B25: =B24+1 -> 46262 | C25: 0 | D25: 0 | I25: =H25-C25 -> 0
B26: =B25+1 -> 46263 | C26: 0 | D26: 0 | I26: =H26-C26 -> 0
B27: Total Week | C27: =SUM(C20:C26) -> -700 | D27: =SUM(D20:D26) -> 700 | E27: LV | H27: =SUM(H20:H26) -> 0 | I27: =SUM(I20:I26) -> 700
B28: =B26+1 -> 46264 | C28: 0 | D28: 0 | I28: =H28-C28 -> 0
B29: =B28+1 -> 46265 | C29: 0 | D29: 0 | I29: =H29-C29 -> 0
B30: =B29+1 -> 46266 | C30: 0 | D30: 700 | E30: LV | I30: =H30-C30 -> 0
B31: =B30+1 -> 46267 | C31: 0 | D31: 0 | I31: =H31-C31 -> 0
B32: =B31+1 -> 46268 | C32: 0 | D32: 0 | I32: =H32-C32 -> 0
B33: =B32+1 -> 46269 | C33: 0 | D33: 0 | I33: =H33-C33 -> 0
B34: =B33+1 -> 46270 | C34: 0 | D34: 0 | I34: =H34-C34 -> 0
B35: Total Week | C35: =SUM(C28:C34) -> 0 | D35: =SUM(D28:D34) -> 700 | H35: =SUM(H28:H34) -> 0 | I35: =SUM(I28:I34) -> 0
B36: Total Period | C36: =SUM(C35+C27+C19+C11) -> -1400 | D36: =SUM(D35+D27+D19+D11) -> 2100 | H36: =SUM(H35+H27+H19+H11) -> 0 | I36: =SUM(I35+I27+I19+I11) -> 1400
B37: Period Activity | C37: =D36+C36 -> 700 | H37: =I36+H36 -> 1400 | I37: =J36+I36 -> 1400
C38: =B34+1 -> 46271 | D38: After Period Close
B39: Ending Period Count of Amount on hand | C39: 1400 | E39: LV
B41: Number of Cash Drawers | C41: 2
...

Sheet OR
C1: Orange
C2: Per Restaurant
C3: Chage Order Deposits | D3: Change Order Received | E3: Initials | F3: Comments | H3: Cash over/ (Short) per R365 Flash report | I3: True Over/ (Short)
B4: =Control!$B$3 -> 46243 | C4: 0 | D4: 0 | H4: -7.38 | I4: =H4-C4 -> -7.38
B5: =B4+1 -> 46244 | C5: 0 | D5: 0 | H5: -13.6 | I5: =H5-C5 -> -13.6
B6: =B5+1 -> 46245 | C6: 0 | D6: 0 | H6: 11.7 | I6: =H6-C6 -> 11.7
B7: =B6+1 -> 46246 | C7: 0 | D7: 0 | H7: 6.26 | I7: =H7-C7 -> 6.26
B8: =B7+1 -> 46247 | C8: 0 | D8: 0 | H8: -2.34 | I8: =H8-C8 -> -2.34
B9: =B8+1 -> 46248 | C9: 0 | D9: 0 | H9: 3.97 | I9: =H9-C9 -> 3.97
B10: =B9+1 -> 46249 | C10: 0 | D10: 0 | H10: 12.03 | I10: =H10-C10 -> 12.03
B11: Total Week | C11: =SUM(C4:C10) -> 0 | D11: =SUM(D4:D10) -> 0 | H11: -51.56 | I11: =SUM(I4:I10) -> 10.64
B12: =B10+1 -> 46250 | C12: 0 | D12: 0 | H12: -6.43 | I12: =H12-C12 -> -6.43
B13: =B12+1 -> 46251 | C13: 0 | D13: 0 | H13: 34.12 | I13: =H13-C13 -> 34.12
B14: =B13+1 -> 46252 | C14: 0 | D14: 0 | H14: -51.56 | I14: =H14-C14 -> -51.56
B15: =B14+1 -> 46253 | C15: 0 | D15: 0 | H15: -8.88 | I15: =H15-C15 -> -8.88
B16: =B15+1 -> 46254 | C16: 0 | D16: 0 | H16: 1.84 | I16: =H16-C16 -> 1.84
B17: =B16+1 -> 46255 | C17: 0 | D17: 0 | H17: 129.78 | I17: =H17-C17 -> 129.78
B18: =B17+1 -> 46256 | C18: 0 | D18: 0 | H18: -250.03 | I18: =H18-C18 -> -250.03
B19: Total Week | C19: =SUM(C12:C18) -> 0 | D19: =SUM(D12:D18) -> 0 | H19: -9.26 | I19: =SUM(I12:I18) -> -151.16
B20: =B18+1 -> 46257 | C20: 0 | D20: 0 | H20: 23 | I20: =H20-C20 -> 23
B21: =B20+1 -> 46258 | C21: 0 | D21: 0 | H21: -11 | I21: =H21-C21 -> -11
B22: =B21+1 -> 46259 | C22: 0 | D22: 0 | H22: -9.38 | I22: =H22-C22 -> -9.38
B23: =B22+1 -> 46260 | C23: 0 | D23: 0 | H23: 127 | I23: =H23-C23 -> 127
B24: =B23+1 -> 46261 | C24: 0 | D24: 0 | H24: -9 | I24: =H24-C24 -> -9
B25: =B24+1 -> 46262 | C25: 0 | D25: 0 | H25: 13 | I25: =H25-C25 -> 13
B26: =B25+1 -> 46263 | C26: 0 | D26: 0 | H26: 9 | I26: =H26-C26 -> 9
B27: Total Week | C27: =SUM(C20:C26) -> 0 | D27: =SUM(D20:D26) -> 0 | H27: =SUM(H20:H26) -> 142.62 | I27: =SUM(I20:I26) -> 142.62
B28: =B26+1 -> 46264 | C28: 0 | D28: 0 | H28: -13.17 | I28: =H28-C28 -> -13.17
B29: =B28+1 -> 46265 | C29: 0 | D29: 0 | H29: -19.54 | I29: =H29-C29 -> -19.54
B30: =B29+1 -> 46266 | C30: 0 | D30: 0 | H30: -23.01 | I30: =H30-C30 -> -23.01
B31: =B30+1 -> 46267 | C31: 0 | D31: 0 | H31: 5.39 | I31: =H31-C31 -> 5.39
B32: =B31+1 -> 46268 | C32: 0 | D32: 0 | H32: 50.3 | I32: =H32-C32 -> 50.3
B33: =B32+1 -> 46269 | C33: 0 | D33: 0 | H33: 9 | I33: =H33-C33 -> 9
B34: =B33+1 -> 46270 | C34: 0 | D34: 0 | H34: 21 | I34: =H34-C34 -> 21
B35: Total Week | C35: =SUM(C28:C34) -> 0 | D35: =SUM(D28:D34) -> 0 | H35: =SUM(H28:H34) -> 29.97 | I35: =SUM(I28:I34) -> 29.97
B36: Total Period | C36: =SUM(C35+C27+C19+C11) -> 0 | D36: =SUM(D35+D27+D19+D11) -> 0 | H36: =SUM(H35+H27+H19+H11) -> 111.77 | I36: =SUM(I35+I27+I19+I11) -> 32.07
B37: Period Activity | C37: =D36+C36 -> 0 | H37: =I36+H36 -> 143.84 | I37: =J36+I36 -> 32.07
C38: =B34+1 -> 46271 | D38: After Period Close
B39: Ending Period Count of Amount on hand | C39: 900 | E39: BL
B41: Number of Cash Drawers | C41: 1
...

Sheet PR
C1: Pico Rivera
C2: Per Restaurant
C3: Chage Order Deposits | D3: Change Order Received | E3: Initials | F3: Comments | H3: Cash over/ (Short) per R365 Flash report | I3: True Over/ (Short)
B4: =Control!$B$3 -> 46243 | C4: 0 | D4: 0 | I4: =H4-C4 -> 0
B5: =B4+1 -> 46244 | C5: 0 | D5: 0 | I5: =H5-C5 -> 0
B6: =B5+1 -> 46245 | C6: 500 | D6: 0 | E6: HF | I6: =H6-C6 -> -500
B7: =B6+1 -> 46246 | C7: 0 | D7: 2000 | E7: VM | I7: =H7-C7 -> 0
B8: =B7+1 -> 46247 | C8: 0 | D8: 0 | I8: =H8-C8 -> 0
B9: =B8+1 -> 46248 | C9: 500 | D9: 0 | E9: HF | I9: =H9-C9 -> -500
B10: =B9+1 -> 46249 | C10: 500 | D10: 0 | E10: HF | I10: =H10-C10 -> -500
B11: Total Week | C11: =SUM(C4:C10) -> 1500 | D11: =SUM(D4:D10) -> 2000 | H11: =SUM(H4:H10) -> 0 | I11: =SUM(I4:I10) -> -1500
B12: =B10+1 -> 46250 | C12: 0 | D12: 0 | I12: =H12-C12 -> 0
B13: =B12+1 -> 46251 | C13: 500 | D13: 0 | E13: HF | I13: =H13-C13 -> -500
B14: =B13+1 -> 46252 | C14: 0 | D14: 0 | I14: =H14-C14 -> 0
B15: =B14+1 -> 46253 | C15: 0 | D15: 0 | I15: =H15-C15 -> 0
B16: =B15+1 -> 46254 | C16: 500 | D16: 0 | E16: VM | I16: =H16-C16 -> -500
B17: =B16+1 -> 46255 | C17: 0 | D17: 0 | I17: =H17-C17 -> 0
B18: =B17+1 -> 46256 | C18: 0 | D18: 0 | I18: =H18-C18 -> 0
B19: Total Week | C19: =SUM(C12:C18) -> 1000 | D19: =SUM(D12:D18) -> 0 | H19: =SUM(H12:H18) -> 0 | I19: =SUM(I12:I18) -> -1000
B20: =B18+1 -> 46257 | C20: 0 | D20: 0 | I20: =H20-C20 -> 0
B21: =B20+1 -> 46258 | C21: 500 | D21: 0 | E21: HF | I21: =H21-C21 -> -500
B22: =B21+1 -> 46259 | C22: 0 | D22: 4000 | E22: VM | F22: didnt recieve bag the week before got double 2 bags this week | I22: =H22-C22 -> 0
B23: =B22+1 -> 46260 | C23: 0 | D23: 0 | I23: =H23-C23 -> 0
B24: =B23+1 -> 46261 | C24: 1500 | D24: 0 | E24: VM | I24: =H24-C24 -> -1500
B25: =B24+1 -> 46262 | C25: 0 | D25: 0 | I25: =H25-C25 -> 0
B26: =B25+1 -> 46263 | C26: 0 | D26: 0 | I26: =H26-C26 -> 0
B27: Total Week | C27: =SUM(C20:C26) -> 2000 | D27: =SUM(D20:D26) -> 4000 | H27: =SUM(H20:H26) -> 0 | I27: =SUM(I20:I26) -> -2000
B28: =B26+1 -> 46264 | C28: 0 | D28: 0 | I28: =H28-C28 -> 0
B29: =B28+1 -> 46265 | C29: 1000 | D29: 0 | E29: HF | I29: =H29-C29 -> -1000
B30: =B29+1 -> 46266 | C30: 0 | D30: 0 | I30: =H30-C30 -> 0
B31: =B30+1 -> 46267 | C31: 0 | D31: 0 | I31: =H31-C31 -> 0
B32: =B31+1 -> 46268 | C32: 500 | D32: 0 | E32: VM | I32: =H32-C32 -> -500
B33: =B32+1 -> 46269 | C33: 500 | D33: 0 | I33: =H33-C33 -> -500
B34: =B33+1 -> 46270 | C34: 500 | D34: 0 | H34: 509 | I34: =H34-C34 -> 9
B35: Total Week | C35: =SUM(C28:C34) -> 2500 | D35: =SUM(D28:D34) -> 0 | H35: =SUM(H28:H34) -> 509 | I35: =SUM(I28:I34) -> -1991
B36: Total Period | C36: =SUM(C35+C27+C19+C11) -> 7000 | D36: =SUM(D35+D27+D19+D11) -> 6000 | H36: =SUM(H35+H27+H19+H11) -> 509 | I36: =SUM(I35+I27+I19+I11) -> -6491
B37: Period Activity | C37: =D36+C36 -> 13000 | H37: =I36+H36 -> -5982 | I37: =J36+I36 -> -6491
C38: =B34+1 -> 46271 | D38: After Period Close
B39: Ending Period Count of Amount on hand | C39: 500 | E39: VM PP
B41: Number of Cash Drawers | C41: 2
...

Sheet RL
C1: Rialto
C2: Per Restaurant
C3: Chage Order Deposits | D3: Change Order Received | E3: Initials | F3: Comments | H3: Cash over/ (Short) per R365 Flash report | I3: True Over/ (Short)
B4: =Control!$B$3 -> 46243 | C4: 0 | D4: 0 | I4: =H4-C4 -> 0
B5: =B4+1 -> 46244 | C5: 0 | D5: 0 | I5: =H5-C5 -> 0
B6: =B5+1 -> 46245 | C6: 0 | D6: 0 | I6: =H6-C6 -> 0
B7: =B6+1 -> 46246 | C7: 0 | D7: 0 | I7: =H7-C7 -> 0
B8: =B7+1 -> 46247 | C8: 0 | D8: 805 | E8: BR | I8: =H8-C8 -> 0
B9: =B8+1 -> 46248 | C9: -805 | D9: 0 | E9: BR | I9: =H9-C9 -> 805
B10: =B9+1 -> 46249 | C10: 0 | D10: 0 | I10: =H10-C10 -> 0
B11: Total Week | C11: =SUM(C4:C10) -> -805 | D11: =SUM(D4:D10) -> 805 | H11: =SUM(H4:H10) -> 0 | I11: =SUM(I4:I10) -> 805
B12: =B10+1 -> 46250 | C12: 0 | D12: 0 | I12: =H12-C12 -> 0
B13: =B12+1 -> 46251 | C13: 0 | D13: 0 | I13: =H13-C13 -> 0
B14: =B13+1 -> 46252 | C14: 0 | D14: 0 | I14: =H14-C14 -> 0
B15: =B14+1 -> 46253 | C15: 0 | D15: 0 | I15: =H15-C15 -> 0
B16: =B15+1 -> 46254 | C16: 0 | D16: 800 | E16: BR | I16: =H16-C16 -> 0
B17: =B16+1 -> 46255 | C17: 0 | D17: 0 | I17: =H17-C17 -> 0
B18: =B17+1 -> 46256 | C18: -800 | D18: 0 | E18: BR | I18: =H18-C18 -> 800
B19: Total Week | C19: =SUM(C12:C18) -> -800 | D19: =SUM(D12:D18) -> 800 | H19: =SUM(H12:H18) -> 0 | I19: =SUM(I12:I18) -> 800
B20: =B18+1 -> 46257 | C20: 0 | D20: 0 | I20: =H20-C20 -> 0
B21: =B20+1 -> 46258 | C21: 0 | D21: 0 | I21: =H21-C21 -> 0
B22: =B21+1 -> 46259 | C22: 0 | D22: 0 | I22: =H22-C22 -> 0
B23: =B22+1 -> 46260 | C23: 0 | D23: 0 | I23: =H23-C23 -> 0
B24: =B23+1 -> 46261 | C24: 0 | D24: 800 | E24: BR | I24: =H24-C24 -> 0
B25: =B24+1 -> 46262 | C25: 0 | D25: 0 | I25: =H25-C25 -> 0
B26: =B25+1 -> 46263 | C26: 800 | D26: 0 | E26: BR | I26: =H26-C26 -> -800
B27: Total Week | C27: =SUM(C20:C26) -> 800 | D27: =SUM(D20:D26) -> 800 | H27: =SUM(H20:H26) -> 0 | I27: =SUM(I20:I26) -> -800
B28: =B26+1 -> 46264 | C28: 0 | D28: 0 | I28: =H28-C28 -> 0
B29: =B28+1 -> 46265 | C29: 0 | D29: 0 | I29: =H29-C29 -> 0
B30: =B29+1 -> 46266 | C30: 0 | D30: 0 | I30: =H30-C30 -> 0
B31: =B30+1 -> 46267 | C31: 0 | D31: 0 | I31: =H31-C31 -> 0
B32: =B31+1 -> 46268 | C32: 0 | D32: 855 | E32: BR | I32: =H32-C32 -> 0
B33: =B32+1 -> 46269 | C33: 0 | D33: 0 | I33: =H33-C33 -> 0
B34: =B33+1 -> 46270 | C34: 855 | D34: 0 | E34: BR | I34: =H34-C34 -> -855
B35: Total Week | C35: =SUM(C28:C34) -> 855 | D35: =SUM(D28:D34) -> 855 | H35: =SUM(H28:H34) -> 0 | I35: =SUM(I28:I34) -> -855
B36: Total Period | C36: =SUM(C35+C27+C19+C11) -> 50 | D36: =SUM(D35+D27+D19+D11) -> 3260 | H36: =SUM(H35+H27+H19+H11) -> 0 | I36: =SUM(I35+I27+I19+I11) -> -50
B37: Period Activity | C37: =D36+C36 -> 3310 | H37: =I36+H36 -> -50 | I37: =J36+I36 -> -50
C38: =B34+1 -> 46271 | D38: After Period Close
B39: Ending Period Count of Amount on hand | C39: 0
B41: Number of Cash Drawers | C41: 3
...

Sheet RV
C1: Riverside
C2: Per Restaurant
C3: Chage Order Deposits | D3: Change Order Received | E3: Initials | F3: Comments | H3: Cash over/ (Short) per R365 Flash report | I3: True Over/ (Short)
B4: =Control!$B$3 -> 46243 | C4: 0 | D4: 0 | I4: =H4-C4 -> 0
B5: =B4+1 -> 46244 | C5: 0 | D5: 0 | I5: =H5-C5 -> 0
B6: =B5+1 -> 46245 | C6: 1225 | D6: 1270 | I6: =H6-C6 -> -1225
B7: =B6+1 -> 46246 | C7: 0 | D7: 0 | I7: =H7-C7 -> 0
B8: =B7+1 -> 46247 | C8: 0 | D8: 0 | I8: =H8-C8 -> 0
B9: =B8+1 -> 46248 | C9: 0 | D9: 0 | I9: =H9-C9 -> 0
B10: =B9+1 -> 46249 | C10: 0 | D10: 0 | I10: =H10-C10 -> 0
B11: Total Week | C11: =SUM(C4:C10) -> 1225 | D11: =SUM(D4:D10) -> 1270 | H11: =SUM(H4:H10) -> 0 | I11: =SUM(I4:I10) -> -1225
B12: =B10+1 -> 46250 | C12: 0 | D12: 0 | I12: =H12-C12 -> 0
B13: =B12+1 -> 46251 | C13: 0 | D13: 0 | I13: =H13-C13 -> 0
B14: =B13+1 -> 46252 | C14: 1270 | D14: 1100 | E14: JP | I14: =H14-C14 -> -1270
B15: =B14+1 -> 46253 | C15: 0 | D15: 0 | I15: =H15-C15 -> 0
B16: =B15+1 -> 46254 | C16: 0 | D16: 0 | I16: =H16-C16 -> 0
B17: =B16+1 -> 46255 | C17: 0 | D17: 0 | I17: =H17-C17 -> 0
B18: =B17+1 -> 46256 | C18: 0 | D18: 0 | I18: =H18-C18 -> 0
B19: Total Week | C19: =SUM(C12:C18) -> 1270 | D19: =SUM(D12:D18) -> 1100 | H19: =SUM(H12:H18) -> 0 | I19: =SUM(I12:I18) -> -1270
B20: =B18+1 -> 46257 | C20: 0 | D20: 0 | I20: =H20-C20 -> 0
B21: =B20+1 -> 46258 | C21: 0 | D21: 0 | I21: =H21-C21 -> 0
B22: =B21+1 -> 46259 | C22: 0 | D22: 0 | I22: =H22-C22 -> 0
B23: =B22+1 -> 46260 | C23: 0 | D23: 0 | H23: 0 | I23: =H23-C23 -> 0
B24: =B23+1 -> 46261 | C24: 0 | D24: 0 | I24: =H24-C24 -> 0
B25: =B24+1 -> 46262 | C25: 0 | D25: 0 | I25: =H25-C25 -> 0
B26: =B25+1 -> 46263 | C26: 0 | D26: 0 | I26: =H26-C26 -> 0
B27: Total Week | C27: =SUM(C20:C26) -> 0 | D27: =SUM(D20:D26) -> 0 | H27: =SUM(H20:H26) -> 0 | I27: =SUM(I20:I26) -> 0
B28: =B26+1 -> 46264 | C28: 0 | D28: 0 | I28: =H28-C28 -> 0
B29: =B28+1 -> 46265 | C29: 0 | D29: 0 | I29: =H29-C29 -> 0
B30: =B29+1 -> 46266 | C30: 0 | D30: 1150 | E30: CA | I30: =H30-C30 -> 0
B31: =B30+1 -> 46267 | C31: 0 | D31: 0 | I31: =H31-C31 -> 0
B32: =B31+1 -> 46268 | C32: 0 | D32: 0 | I32: =H32-C32 -> 0
B33: =B32+1 -> 46269 | C33: 0 | D33: 0 | I33: =H33-C33 -> 0
B34: =B33+1 -> 46270 | C34: 1100 | D34: 0 | E34: JP | I34: =H34-C34 -> -1100
B35: Total Week | C35: =SUM(C28:C34) -> 1100 | D35: =SUM(D28:D34) -> 1150 | H35: =SUM(H28:H34) -> 0 | I35: =SUM(I28:I34) -> -1100
B36: Total Period | C36: =SUM(C35+C27+C19+C11) -> 3595 | D36: =SUM(D35+D27+D19+D11) -> 3520 | H36: =SUM(H35+H27+H19+H11) -> 0 | I36: =SUM(I35+I27+I19+I11) -> -3595
B37: Period Activity | C37: =D36+C36 -> 7115 | H37: =I36+H36 -> -3595 | I37: =J36+I36 -> -3595
C38: =B34+1 -> 46271 | D38: After Period Close
B39: Ending Period Count of Amount on hand | C39: 1150 | E39: JP
B41: Number of Cash Drawers | C41: 2
...

Sheet SA
C1: Santa Ana
C2: Per Restaurant
C3: Chage Order Deposits | D3: Change Order Received | E3: Initials | F3: Comments | H3: Cash over/ (Short) per R365 Flash report | I3: True Over/ (Short)
B4: =Control!$B$3 -> 46243 | C4: 0 | D4: 499 | F4: 499 change order left unpaid from previous period. | H4: 273 | I4: =H4-C4 -> 273
B5: =B4+1 -> 46244 | C5: 251 | D5: 0 | H5: 201 | I5: =H5-C5 -> -50
B6: =B5+1 -> 46245 | C6: 0 | D6: 0 | H6: 537 | I6: =H6-C6 -> 537
B7: =B6+1 -> 46246 | C7: 245 | D7: 905 | H7: -871 | I7: =H7-C7 -> -1116
B8: =B7+1 -> 46247 | C8: 300 | D8: 0 | H8: 552 | I8: =H8-C8 -> 252
B9: =B8+1 -> 46248 | C9: 0 | D9: 0 | H9: 18 | I9: =H9-C9 -> 18
B10: =B9+1 -> 46249 | C10: 0 | D10: 0 | H10: 22 | I10: =H10-C10 -> 22
B11: Total Week | C11: =SUM(C4:C10) -> 796 | D11: =SUM(D4:D10) -> 1404 | H11: =SUM(H4:H10) -> 732 | I11: =SUM(I4:I10) -> -64
B12: =B10+1 -> 46250 | C12: 300 | D12: 0 | H12: 569 | I12: =H12-C12 -> 269
B13: =B12+1 -> 46251 | C13: 0 | D13: 0 | H13: 24 | I13: =H13-C13 -> 24
B14: =B13+1 -> 46252 | C14: 200 | D14: 830 | E14: ema | H14: -434 | I14: =H14-C14 -> -634
B15: =B14+1 -> 46253 | C15: 200 | D15: 0 | H15: 430 | I15: =H15-C15 -> 230
B16: =B15+1 -> 46254 | C16: 0 | D16: 0 | H16: 111 | I16: =H16-C16 -> 111
B17: =B16+1 -> 46255 | C17: 0 | D17: 0 | H17: 106 | I17: =H17-C17 -> 106
B18: =B17+1 -> 46256 | C18: 300 | D18: 0 | H18: 625 | I18: =H18-C18 -> 325
B19: Total Week | C19: =SUM(C12:C18) -> 1000 | D19: =SUM(D12:D18) -> 830 | H19: =SUM(H12:H18) -> 1431 | I19: =SUM(I12:I18) -> 431
B20: =B18+1 -> 46257 | C20: 150 | D20: 0 | H20: -42 | I20: =H20-C20 -> -192
B21: =B20+1 -> 46258 | C21: 335 | D21: 0 | H21: 590 | I21: =H21-C21 -> 255
B22: =B21+1 -> 46259 | C22: 0 | D22: 900 | E22: ema | H22: -812 | I22: =H22-C22 -> -812
B23: =B22+1 -> 46260 | C23: 105 | D23: 0 | H23: 112 | I23: =H23-C23 -> 7
B24: =B23+1 -> 46261 | C24: 500 | D24: 0 | H24: 473 | I24: =H24-C24 -> -27
B25: =B24+1 -> 46262 | C25: 300 | D25: 755 | E25: ema | H25: 309 | I25: =H25-C25 -> 9
B26: =B25+1 -> 46263 | C26: 420 | D26: 0 | H26: 459 | I26: =H26-C26 -> 39
B27: Total Week | C27: =SUM(C20:C26) -> 1810 | D27: =SUM(D20:D26) -> 1655 | H27: =SUM(H20:H26) -> 1089 | I27: =SUM(I20:I26) -> -721
B28: =B26+1 -> 46264 | C28: 0 | D28: 0 | H28: 8 | I28: =H28-C28 -> 8
B29: =B28+1 -> 46265 | C29: 0 | D29: 0 | H29: 10 | I29: =H29-C29 -> 10
B30: =B29+1 -> 46266 | C30: 0 | D30: 0 | H30: 13 | I30: =H30-C30 -> 13
B31: =B30+1 -> 46267 | C31: 0 | D31: 0 | H31: 15 | I31: =H31-C31 -> 15
B32: =B31+1 -> 46268 | C32: 435 | D32: 980 | E32: ema | H32: 425 | I32: =H32-C32 -> -10
B33: =B32+1 -> 46269 | C33: 250 | D33: 0 | H33: 116 | I33: =H33-C33 -> -134
B34: =B33+1 -> 46270 | C34: 0 | D34: 0 | H34: -30 | I34: =H34-C34 -> -30
B35: Total Week | C35: =SUM(C28:C34) -> 685 | D35: =SUM(D28:D34) -> 980 | H35: =SUM(H28:H34) -> 557 | I35: =SUM(I28:I34) -> -128
B36: Total Period | C36: =SUM(C35+C27+C19+C11) -> 4291 | D36: =SUM(D35+D27+D19+D11) -> 4869 | F36: 0 | H36: =SUM(H35+H27+H19+H11) -> 3809 | I36: =SUM(I35+I27+I19+I11) -> -482
B37: Period Activity | C37: =D36+C36 -> 9160 | H37: =I36+H36 -> 3327 | I37: =J36+I36 -> -482
C38: =B34+1 -> 46271 | D38: After Period Close
B39: Ending Period Count of Amount on hand | C39: 805 | E39: ema
B41: Number of Cash Drawers | C41: 2
...

Sheet SL
C1: Slauson
C2: Per Restaurant
C3: Chage Order Deposits | D3: Change Order Received | E3: Initials | F3: Comments | H3: Cash over/ (Short) per R365 Flash report | I3: True Over/ (Short)
B4: =Control!$B$3 -> 46243 | C4: 0 | D4: 2376 | E4: RG | F4: Prior Period 8 owed $2376 | H4: -123.83 | I4: =H4-C4 -> -123.83
B5: =B4+1 -> 46244 | C5: 0 | D5: 0 | H5: 39.51 | I5: =H5-C5 -> 39.51
B6: =B5+1 -> 46245 | C6: 0 | D6: 0 | H6: -9.21 | I6: =H6-C6 -> -9.21
B7: =B6+1 -> 46246 | C7: 0 | D7: 0 | H7: 267.36 | I7: =H7-C7 -> 267.36
B8: =B7+1 -> 46247 | C8: 0 | D8: 0 | H8: 289.63 | I8: =H8-C8 -> 289.63
B9: =B8+1 -> 46248 | C9: 0 | D9: 0 | H9: 499.01 | I9: =H9-C9 -> 499.01
B10: =B9+1 -> 46249 | C10: 0 | D10: 0 | H10: -646.65 | I10: =H10-C10 -> -646.65
B11: Total Week | C11: =SUM(C4:C10) -> 0 | D11: =SUM(D4:D10) -> 2376 | H11: =SUM(H4:H10) -> 315.82 | I11: =SUM(I4:I10) -> 315.82
B12: =B10+1 -> 46250 | C12: 0 | D12: 0 | H12: -35.05 | I12: =H12-C12 -> -35.05
B13: =B12+1 -> 46251 | C13: 0 | D13: 0 | H13: -105.15 | I13: =H13-C13 -> -105.15
B14: =B13+1 -> 46252 | C14: 0 | D14: 0 | H14: -202.16 | I14: =H14-C14 -> -202.16
B15: =B14+1 -> 46253 | C15: 0 | D15: 0 | E15: RG | H15: 276.95 | I15: =H15-C15 -> 276.95
B16: =B15+1 -> 46254 | C16: 0 | D16: 0 | E16: RG | H16: 144.49 | I16: =H16-C16 -> 144.49
B17: =B16+1 -> 46255 | C17: 0 | D17: 0 | H17: -213.92 | I17: =H17-C17 -> -213.92
B18: =B17+1 -> 46256 | C18: 0 | D18: 0 | H18: 12.82 | I18: =H18-C18 -> 12.82
B19: Total Week | C19: =SUM(C12:C18) -> 0 | D19: =SUM(D12:D18) -> 0 | H19: =SUM(H12:H18) -> -122.02 | I19: =SUM(I12:I18) -> -122.02
B20: =B18+1 -> 46257 | C20: 0 | D20: 0 | H20: -112.87 | I20: =H20-C20 -> -112.87
B21: =B20+1 -> 46258 | C21: 0 | D21: 0 | H21: -311.29 | I21: =H21-C21 -> -311.29
B22: =B21+1 -> 46259 | C22: 0 | D22: 2990 | E22: Rg | H22: 289.37 | I22: =H22-C22 -> 289.37
B23: =B22+1 -> 46260 | C23: 0 | D23: 0 | H23: -53.52 | I23: =H23-C23 -> -53.52
B24: =B23+1 -> 46261 | C24: 0 | D24: 0 | H24: 45.06 | I24: =H24-C24 -> 45.06
B25: =B24+1 -> 46262 | C25: 0 | D25: 0 | H25: -41.33 | I25: =H25-C25 -> -41.33
B26: =B25+1 -> 46263 | C26: 0 | D26: 0 | H26: -471.97 | I26: =H26-C26 -> -471.97
B27: Total Week | C27: =SUM(C20:C26) -> 0 | D27: =SUM(D20:D26) -> 2990 | H27: =SUM(H20:H26) -> -656.55 | I27: =SUM(I20:I26) -> -656.55
B28: =B26+1 -> 46264 | C28: 0 | D28: 0 | H28: 444.88 | I28: =H28-C28 -> 444.88
B29: =B28+1 -> 46265 | C29: 0 | D29: 0 | H29: -17.92 | I29: =H29-C29 -> -17.92
B30: =B29+1 -> 46266 | C30: 0 | D30: 0 | H30: -4.1 | I30: =H30-C30 -> -4.1
B31: =B30+1 -> 46267 | C31: 0 | D31: 0 | H31: 73.38 | I31: =H31-C31 -> 73.38
B32: =B31+1 -> 46268 | C32: 0 | D32: 0 | H32: -717.37 | I32: =H32-C32 -> -717.37
B33: =B32+1 -> 46269 | C33: 0 | D33: 0 | H33: 827.41 | I33: =H33-C33 -> 827.41
B34: =B33+1 -> 46270 | C34: 0 | D34: 0 | H34: -112.1 | I34: =H34-C34 -> -112.1
B35: Total Week | C35: =SUM(C28:C34) -> 0 | D35: =SUM(D28:D34) -> 0 | H35: =SUM(H28:H34) -> 494.18 | I35: =SUM(I28:I34) -> 494.18
B36: Total Period | C36: =SUM(C35+C27+C19+C11) -> 0 | D36: =SUM(D35+D27+D19+D11) -> 5366 | H36: =SUM(H35+H27+H19+H11) -> 31.43 | I36: =SUM(I35+I27+I19+I11) -> 31.43
B37: Period Activity | C37: =D36+C36 -> 5366 | H37: =I36+H36 -> 62.86 | I37: =J36+I36 -> 31.43
C38: =B34+1 -> 46271 | D38: After Period Close
B39: Ending Period Count of Amount on hand | C39: 5366 | F39: owed 5366
B41: Number of Cash Drawers | C41: 2
...

Sheet ST
C1: South Torrance
C3: Chage Order Deposits | D3: Change Order Received | E3: Initials | F3: Comments | H3: Cash over/ (Short) per R365 Flash report | I3: True Over/ (Short)
